Workbook

Sheet Open Order PCT to Viatris
A1: BRAND NAME | B1: Total Open PO Quantity | C1: PO.NO (1) | D1: PO Quantity | E1: PO.NO(2) | F1: PO Quantity | G1: PO.NO(3) | H1: PO Quantity | I1: PO.NO(4) | J1: PO Quantity
A2: VALPROATE Officine | B2: ='PCT order to Viatris '!D50 -> 56000 | C2: ='PCT order to Viatris '!F50 -> 25GP10I0138 | D2: =B2 -> 56000
A3: ZOLPIDEM | B3: ='PCT order to Viatris '!D54 -> 3600 | C3: ='PCT order to Viatris '!F54 -> 25GP10I0138 | D3: ='PCT order to Viatris '!E54 -> 3600
A4: DOBUTAMINE | B4: ='PCT order to Viatris '!D56 -> 7200 | C4: ='PCT order to Viatris '!F56 -> 26AO50I0025 | D4: ='PCT order to Viatris '!E56 -> 7200
A5: METHOTREXATE 100mg/ml (5G) | B5: ='PCT order to Viatris '!D58 -> 60 | C5: ='PCT order to Viatris '!F58 -> 26AO50I0025 | D5: ='PCT order to Viatris '!D58 -> 60
A6: SUFENTANIL 10µg/2ml | B6: ='PCT order to Viatris '!D60 -> 6500 | C6: ='PCT order to Viatris '!F60 -> 25AO50I0012 | D6: ='PCT order to Viatris '!E61 -> 6500
A7: SUFENTANIL 50µg/10ml | B7: ='PCT order to Viatris '!D62 -> 2280 | C7: ='PCT order to Viatris '!F62 -> 26AO50I0041 | D7: ='PCT order to Viatris '!E62 -> 1140 | E7: ='PCT order to Viatris '!H62 -> 26AO50I0042 | F7: ='PCT order to Viatris '!G62 -> 1140
A8: FLECAINE 100mg | B8: ='PCT order to Viatris '!D64 -> 10000 | C8: ='PCT order to Viatris '!F64 -> 25GG10I0110 | D8: ='PCT order to Viatris '!E64 -> 10000
A9: FLECAINE LP 200mg | B9: ='PCT order to Viatris '!D66 -> 9000 | C9: ='PCT order to Viatris '!F66 -> 25GP10I0177 | D9: ='PCT order to Viatris '!E66 -> 9000
A10: FLECAINE LP 50mg | B10: ='PCT order to Viatris '!D69 -> 9000 | C10: ='PCT order to Viatris '!F69 -> 25GP10I0114 | D10: ='PCT order to Viatris '!E69 -> 4000 | E10: ='PCT order to Viatris '!H69 -> 25GP10I0177 | F10: ='PCT order to Viatris '!G69 -> 5000
A11: FLECAINE LP 100mg
A12: XANAX RETARD 0.5mg | B12: ='PCT order to Viatris '!D41 -> 30000 | C12: ='PCT order to Viatris '!F41 -> 26MP10I0014 | D12: ='PCT order to Viatris '!D41 -> 30000
A13: XANAX RETARD 1mg | B13: ='PCT order to Viatris '!D44 -> 16718 | C13: ='PCT order to Viatris '!F44 -> 25GP10I0089 | D13: ='PCT order to Viatris '!E44 -> 6000 | E13: ='PCT order to Viatris '!H44 -> 25GP10I0161 | F13: ='PCT order to Viatris '!G44 -> 10718
A14: XANAX 0.75mg/ml Gttes.Buv. | B14: ='PCT order to Viatris '!D48 -> 40000 | C14: ='PCT order to Viatris '!F48 -> 25GP10I0089 | D14: ='PCT order to Viatris '!E48 -> 30000 | E14: ='PCT order to Viatris '!H48 -> 25GP10I0161 | F14: ='PCT order to Viatris '!G48 -> 10000
A15: EFEXOR. XL 150mg Gél. LP | B15: ='PCT order to Viatris '!D12 -> 600 | C15: ='PCT order to Viatris '!F12 -> 26MP10I0002 | D15: ='PCT order to Viatris '!E13 -> 600
A16: LYRICA 75mg Gél. Bt56 | B16: ='PCT order to Viatris '!D25 -> 2500 | C16: ='PCT order to Viatris '!F25 -> 26MP10I0002 | D16: ='PCT order to Viatris '!D25 -> 2500
A17: EFFEXOR LP 37.5mg Gél. LP | B17: ='PCT order to Viatris '!D14 -> 8000 | C17: ='PCT order to Viatris '!F14 -> 25GG10I0087 | D17: ='PCT order to Viatris '!E14 -> 2000 | E17: ='PCT order to Viatris '!H14 -> 25GG10I0126 | F17: ='PCT order to Viatris '!G14 -> 6000
A18: EFFEXOR LP 75mg Gél. LP | B18: ='PCT order to Viatris '!D17 -> 34748 | C18: ='PCT order to Viatris '!F17 -> 25GG10I0087 | D18: ='PCT order to Viatris '!E17 -> 1748 | E18: ='PCT order to Viatris '!H17 -> 25GG10I0126 | F18: ='PCT order to Viatris '!G17 -> 33000
A19: XALATAN 50mcg/ml Collyre | B19: ='PCT order to Viatris '!D39 -> 12000 | C19: ='PCT order to Viatris '!F39 -> 25GG10I0126 | D19: ='PCT order to Viatris '!E37 -> 12000
A20: CADUET 10mg/10mg Comp.Pell. | B20: ='PCT order to Viatris '!D2 -> 6850 | C20: ='PCT order to Viatris '!F2 -> 24GG10I0147 | D20: ='PCT order to Viatris '!E2 -> 1250 | E20: ='PCT order to Viatris '!H2 -> 25GG10I0087 | F20: ='PCT order to Viatris '!G2 -> 4900 | G20: ='PCT order to Viatris '!J2 -> 25GG10I0126 | H20: ='PCT order to Viatris '!I2 -> 700
A21: CADUET 5mg/10mg Comp.Pell. | B21: ='PCT order to Viatris '!D10 -> 3200 | C21: ='PCT order to Viatris '!F10 -> 25GG10I0087 | D21: ='PCT order to Viatris '!E10 -> 1600 | E21: ='PCT order to Viatris '!H10 -> 25GG10I0126 | F21: ='PCT order to Viatris '!G10 -> 1600
A22: LYRICA 150mg Gél. | B22: ='PCT order to Viatris '!D20 -> 3000 | C22: ='PCT order to Viatris '!F20 -> 25GG10I0087 | D22: ='PCT order to Viatris '!E20 -> 1350 | E22: ='PCT order to Viatris '!H20 -> 25GG10I0126 | F22: ='PCT order to Viatris '!G20 -> 1650
A23: LYRICA 75mg Gél. Bt14 | B23: ='PCT order to Viatris '!D22 -> 2400 | C23: ='PCT order to Viatris '!F22 -> 25GG10I0087 | D23: ='PCT order to Viatris '!E22 -> 2400
A24: XALACOM 50mcg + 5mg/ml Collyre | B24: ='PCT order to Viatris '!D37 -> 12000 | C24: ='PCT order to Viatris '!F37 -> 25GG10I0126 | D24: ='PCT order to Viatris '!D37 -> 12000
A25: TAHOR 80mg Comp.Pell. | B25: ='PCT order to Viatris '!D27 -> 1000 | C25: ='PCT order to Viatris '!F27 -> 25GP10I0160 | D25: ='PCT order to Viatris '!E27 -> 1000
A26: VIAGRA 25mg Comp.Pell. | B26: ='PCT order to Viatris '!D32 -> 3200 | C26: ='PCT order to Viatris '!F32 -> 25GP10I0160 | D26: ='PCT order to Viatris '!E32 -> 1920 | E26: ='PCT order to Viatris '!H32 -> UG25GP10I0160 | F26: ='PCT order to Viatris '!G32 -> 1280
A27: VIAGRA 50mg Comp.Pell. | B27: ='PCT order to Viatris '!D34 -> 24000 | C27: ='PCT order to Viatris '!F34 -> 25GP10I0102 | D27: ='PCT order to Viatris '!E34 -> 4875 | E27: ='PCT order to Viatris '!H34 -> UG25GP10I0102 | F27: ='PCT order to Viatris '!G34 -> 3125 | G27: ='PCT order to Viatris '!J34 -> 25GP10I0160 | H27: ='PCT order to Viatris '!I34 -> 10400 | I27: ='PCT order to Viatris '!L34 -> UG25GP10I0160 | J27: ='PCT order to Viatris '!K34 -> 5600
A28: VIAGRA 100mg Comp.Pell. | B28: ='PCT order to Viatris '!D29 -> 40925 | C28: ='PCT order to Viatris '!F29 -> 25GP10I0102 | D28: ='PCT order to Viatris '!E29 -> 9410 | E28: ='PCT order to Viatris '!H29 -> UG25GP10I0102 | F28: ='PCT order to Viatris '!G29 -> 5515 | G28: ='PCT order to Viatris '!J29 -> 25GP10I0160 | H28: ='PCT order to Viatris '!I29 -> 16900 | I28: ='PCT order to Viatris '!L29 -> UG25GP10I0160 | J28: ='PCT order to Viatris '!K29 -> 9100

Sheet Viatris Sales Data
A1: Viatris Sales Data 2025
A2: BRAND NAME | B2: 45658 | C2: 45689 | D2: 45717 | E2: 45748 | F2: 45778 | G2: 45809 | H2: 45839 | I2: 45870 | J2: 45901 | K2: 45931 | L2: 45962 | M2: 45992 | N2: Total 2025
A3: VALPROATE Officine | B3: 8500 | C3: 8500 | E3: 8000 | G3: 13500 | J3: 30000 | M3: 10000 | N3: =SUM(B3:M3) -> 78500
A4: ZOLPIDEM | C4: 4800 | E4: 3400 | G4: 3400 | H4: 3400 | J4: 8000 | N4: =SUM(B4:M4) -> 23000
A5: METHYLPREDNISOLONE | B5: 0 | C5: 0 | E5: 0 | N5: =SUM(B5:M5) -> 0
A6: METHOTREXATE 5mg/2ml | F6: 500 | I6: 1600 | J6: 320 | N6: =SUM(B6:M6) -> 2420
A7: DOBUTAMINE | C7: 2443 | H7: 1261 | N7: =SUM(B7:M7) -> 3704
A8: METHOTREXATE 25mg/20ml | B8: 0 | C8: 0 | D8: 0 | F8: 0 | G8: 0 | H8: 0 | I8: 0 | J8: 0 | K8: 0 | M8: 0 | N8: =SUM(B8:M8) -> 0
A9: METHOTREXATE 50mg/2ml | D9: 400 | H9: 800 | N9: =SUM(B9:M9) -> 1200
A10: AZATHIOPRINE | E10: 24000 | G10: 24000 | K10: 38400 | N10: =SUM(B10:M10) -> 86400
A11: METHOTREXATE 100mg/ml (5G) | M11: 0 | N11: =SUM(B11:M11) -> 0
A12: SUFENTANIL 10µg/2ml | E12: 3000 | G12: 3500 | L12: 2000 | N12: =SUM(B12:M12) -> 8500
A13: CAPECITABINE | G13: 4800 | M13: 4800 | N13: =SUM(B13:M13) -> 9600
A14: SUFENTANIL 50µg/10ml | C14: 900 | F14: 1140 | I14: 1140 | M14: 2280 | N14: =SUM(B14:M14) -> 5460
A15: PIPER/TAZO 2g/250mg | B15: 3780 | N15: =SUM(B15:M15) -> 3780
A16: PIPER/TAZO 4g/500mg | B16: 0 | D16: 0 | F16: 0 | G16: 0 | H16: 0 | I16: 0 | J16: 0 | K16: 0 | L16: 0 | M16: 0 | N16: =SUM(B16:M16) -> 0
A17: LEPONEX 25mg | G17: 2737 | N17: =SUM(B17:M17) -> 2737
A18: LEPONEX 100mg | C18: 12852 | D18: 7757 | J18: 243 | N18: =SUM(B18:M18) -> 20852
A19: FLECAINE 100mg | C19: 11000 | D19: 7000 | E19: 11250 | G19: 11250 | J19: 8726 | L19: =1274+10000 -> 11274 | N19: =SUM(B19:M19) -> 60500
A20: FLECAINE LP 200mg | D20: 5500 | H20: 7000 | M20: 2000 | N20: =SUM(B20:M20) -> 14500
A21: FLECAINE LP 50mg | D21: 3500 | G21: 6500 | K21: 1530 | L21: 170 | N21: =SUM(B21:M21) -> 11700
A22: FLECAINE LP 100mg | D22: 13500 | E22: 4985 | G22: 15015 | L22: 10000 | N22: =SUM(B22:M22) -> 43500
A23: XANAX RETARD 0.5mg | D23: 10000 | E23: 10000 | I23: 9827 | J23: 10000 | M23: 10000 | N23: =SUM(B23:M23) -> 49827
A24: XANAX RETARD 1mg | B24: =9200+9200 -> 18400 | D24: =18000+10000 -> 28000 | G24: =16000+10000 -> 26000 | K24: =5457+10000 -> 15457 | N24: =SUM(B24:M24) -> 87857
A25: XANAX 0.75mg/ml Gttes.Buv. | D25: 10000 | F25: 7500 | I25: 2500 | J25: 9985 | K25: 10000 | L25: 5000 | N25: =SUM(B25:M25) -> 44985
A26: EFEXOR. XL 150mg Gél. LP | E26: 500 | N26: =SUM(B26:M26) -> 500
A27: LYRICA 75mg Gél. Bt56 | E27: 3000 | N27: =SUM(B27:M27) -> 3000
A28: EFFEXOR LP 37.5mg Gél. LP | C28: 4200 | G28: 1200 | I28: 6000 | N28: =SUM(B28:M28) -> 11400
A29: EFFEXOR LP 75mg Gél. LP | C29: 20220 | G29: 23040 | J29: 11520 | N29: =SUM(B29:M29) -> 54780
A30: XALATAN 50mcg/ml Collyre | E30: 23000 | H30: 10000 | I30: 10000 | K30: 21000 | N30: =SUM(B30:M30) -> 64000
A31: CADUET 10mg/10mg Comp.Pell. | H31: 1960 | J31: 1500 | N31: =SUM(B31:M31) -> 3460
A32: CADUET 5mg/10mg Comp.Pell. | C32: 3220 | H32: 1590 | J32: 1700 | N32: =SUM(B32:M32) -> 6510
A33: LYRICA 150mg Gél. | C33: 3000 | H33: 1000 | J33: 800 | N33: =SUM(B33:M33) -> 4800
A34: LYRICA 75mg Gél. Bt14 | H34: 3500 | M34: 500 | N34: =SUM(B34:M34) -> 4000
A35: XALACOM 50mcg + 5mg/ml Collyre | C35: 20618 | F35: 20647 | H35: 23608 | K35: 8000 | N35: =SUM(B35:M35) -> 72873
A36: TAHOR 80mg Comp.Pell. | E36: 1000 | G36: 180 | K36: 400 | N36: =SUM(B36:M36) -> 1580
A37: VIAGRA 25mg Comp.Pell. | G37: =1460+2504 -> 3964 | H37: 1620 | N37: =SUM(B37:M37) -> 5584
A38: VIAGRA 50mg Comp.Pell. | D38: =5600+9300 -> 14900 | G38: =10400+5600 -> 16000 | M38: 8000 | N38: =SUM(B38:M38) -> 38900
A39: VIAGRA 100mg Comp.Pell. | D39: =5075+9750 -> 14825 | G39: 4375 | H39: =5085+10000 -> 15085 | J39: =11400+5990 -> 17390 | M39: 10000 | N39: =SUM(B39:M39) -> 61675
B40: =SUM(B3:B39) -> 30680 | C40: =SUM(C3:C39) -> 91753 | D40: =SUM(D3:D39) -> 115382 | E40: =SUM(E3:E39) -> 92135 | F40: =SUM(F3:F39) -> 29787 | G40: =SUM(G3:G39) -> 159461 | H40: =SUM(H3:H39) -> 70824 | I40: =SUM(I3:I39) -> 31067 | ... N40: =SUM(N3:N39) -> 892084
...

Sheet PCT Sales Data
A1: PCT Sales Data 2025
A2: BRAND NAME | B2: 45658 | C2: 45689 | D2: 45717 | E2: 45748 | F2: 45778 | G2: 45809 | H2: 45839 | I2: 45870 | J2: 45901 | K2: 45931 | L2: 45962 | M2: 45992 | N2: Total 2025
A3: VALPROATE Officine | B3: 4394 | C3: 6941 | D3: 6587 | E3: 6771 | F3: 5755 | G3: 3979 | H3: 5714 | I3: 4923 | J3: 7638 | K3: 7898 | L3: 9207 | M3: 6236 | N3: =SUM(B3:M3) -> 76043
A4: ZOLPIDEM | B4: 1680 | C4: 2050 | D4: 1620 | E4: 1985 | F4: 1970 | G4: 1280 | H4: 2990 | I4: 1450 | J4: 1370 | K4: 2160 | L4: 1620 | M4: 1705 | N4: =SUM(B4:M4) -> 21880
A5: METHYLPREDNISOLONE | B5: 0 | C5: 0 | E5: 0 | F5: 13 | G5: 216 | H5: 305 | I5: 148 | J5: 100 | K5: 44 | L5: 10 | M5: 0 | N5: =SUM(B5:M5) -> 836
A6: METHOTREXATE 5mg/2ml | B6: 6 | C6: 0 | D6: 0 | E6: 64 | F6: 340 | G6: 79 | H6: 772 | I6: 465 | J6: 393 | K6: 288 | L6: 19 | M6: 0 | N6: =SUM(B6:M6) -> 2426
A7: DOBUTAMINE | B7: 1 | C7: 513 | D7: 366 | E7: 624 | F7: 327 | G7: 423 | H7: 169 | I7: 333 | J7: 216 | K7: 321 | L7: 263 | M7: 132 | N7: =SUM(B7:M7) -> 3688
A8: METHOTREXATE 25mg/20ml | B8: 0 | C8: 0 | D8: 0 | F8: 0 | G8: 0 | H8: 0 | I8: 0 | J8: 0 | K8: 0 | M8: 0 | N8: =SUM(B8:M8) -> 0
A9: METHOTREXATE 50mg/2ml | B9: 0 | C9: 0 | D9: 0 | E9: 0 | F9: 0 | G9: 17 | H9: 105 | I9: 49 | J9: 103 | K9: 93 | L9: 165 | M9: 153 | N9: =SUM(B9:M9) -> 685
A10: AZATHIOPRINE | B10: 4623 | C10: 8190 | D10: 5251 | E10: 6149 | F10: 6237 | G10: 7149 | H10: 5327 | I10: 6123 | J10: 6188 | K10: 5481 | L10: 5818 | M10: 6592 | N10: =SUM(B10:M10) -> 73128
A11: METHOTREXATE 100mg/ml (5G) | M11: 0 | N11: =SUM(B11:M11) -> 0
A12: SUFENTANIL 10µg/2ml | B12: 685 | C12: 327 | D12: 147 | E12: 9 | F12: 0 | G12: 23 | H12: 1035 | I12: 1565 | J12: 1309 | K12: 1531 | L12: 1322 | M12: 1088 | N12: =SUM(B12:M12) -> 9041
A13: CAPECITABINE | B13: 4 | C13: 5 | D13: 0 | E13: 2 | F13: 0 | G13: 0 | H13: 0 | I13: 0 | J13: 45 | K13: 157 | L13: 474 | M13: 666 | N13: =SUM(B13:M13) -> 1353
A14: SUFENTANIL 50µg/10ml | B14: 510 | C14: 342 | D14: 377 | E14: 186 | F14: 263 | G14: 422 | H14: 936 | I14: 609 | J14: 698 | K14: 525 | L14: 551 | M14: 439 | N14: =SUM(B14:M14) -> 5858
A15: PIPER/TAZO 2g/250mg | B15: 1150 | C15: 715 | D15: 20 | E15: 435 | F15: 300 | G15: 110 | H15: 794 | I15: 326 | J15: 401 | K15: 279 | L15: 100 | M15: 0 | N15: =SUM(B15:M15) -> 4630
A16: PIPER/TAZO 4g/500mg | B16: 0 | C16: 25 | D16: 0 | F16: 0 | G16: 0 | H16: 0 | I16: 0 | J16: 0 | K16: 0 | L16: 0 | M16: 0 | N16: =SUM(B16:M16) -> 25
A17: LEPONEX 25mg | B17: 305 | C17: 248 | D17: 105 | E17: 33 | F17: 0 | G17: 1387 | H17: 676 | I17: 593 | J17: 88 | K17: 38 | L17: 5 | M17: 0 | N17: =SUM(B17:M17) -> 3478
A18: LEPONEX 100mg | B18: 244 | C18: 926 | D18: 5441 | E18: 3183 | F18: 4063 | G18: 3310 | H18: 1890 | I18: 690 | J18: 1175 | K18: 234 | L18: 5 | M18: 36 | N18: =SUM(B18:M18) -> 21197
A19: FLECAINE 100mg | B19: 5013 | C19: 7203 | D19: 3296 | E19: 1856 | F19: 1817 | G19: 2779 | H19: 1566 | I19: 3182 | J19: 3374 | K19: 3499 | L19: 3464 | M19: 3075 | N19: =SUM(B19:M19) -> 40124
A20: FLECAINE LP 200mg | B20: 1421 | C20: 1953 | D20: 1046 | E20: 655 | F20: 1670 | G20: 1860 | H20: 945 | I20: 2106 | J20: 2615 | K20: 1816 | L20: 1968 | M20: 1734 | N20: =SUM(B20:M20) -> 19789
A21: FLECAINE LP 50mg | B21: 487 | C21: 835 | D21: 961 | E21: 790 | F21: 1120 | G21: 1625 | H21: 1323 | I21: 1356 | J21: 1522 | K21: 1859 | L21: 1379 | M21: 1799 | N21: =SUM(B21:M21) -> 15056
A22: FLECAINE LP 100mg | B22: 2222 | C22: 3575 | D22: 2977 | E22: 2970 | F22: 4790 | G22: 3796 | H22: 2941 | I22: 5262 | J22: 5774 | K22: 4917 | L22: 3897 | M22: 5012 | N22: =SUM(B22:M22) -> 48133
A23: XANAX RETARD 0.5mg | B23: 4647 | C23: 259 | D23: 3376 | E23: 2993 | F23: 3663 | G23: 4251 | H23: 3849 | I23: 1833 | J23: 3243 | K23: 5116 | L23: 5728 | M23: 4978 | N23: =SUM(B23:M23) -> 43936
A24: XANAX RETARD 1mg | B24: 7066 | C24: 5718 | D24: 6787 | E24: 4961 | F24: 5031 | G24: 3953 | H24: 3852 | I24: 5496 | J24: 5939 | K24: 5162 | L24: 6419 | M24: 5246 | N24: =SUM(B24:M24) -> 65630
A25: XANAX 0.75mg/ml Gttes.Buv. | B25: 10899 | C25: 95 | D25: 3891 | E25: 2668 | F25: 4579 | G25: 4460 | H25: 5578 | I25: 2012 | J25: 46 | K25: 10069 | L25: 6768 | M25: 3712 | N25: =SUM(B25:M25) -> 54777
A26: EFEXOR. XL 150mg Gél. LP | B26: 63 | C26: 105 | D26: 102 | E26: 46 | F26: 83 | G26: 119 | H26: 85 | I26: 187 | J26: 135 | K26: 32 | L26: 107 | M26: 42 | N26: =SUM(B26:M26) -> 1106
A27: LYRICA 75mg Gél. Bt56 | B27: 234 | C27: 336 | D27: 222 | E27: 336 | F27: 456 | G27: 372 | H27: 282 | I27: 450 | J27: 402 | K27: 468 | L27: 312 | M27: 306 | N27: =SUM(B27:M27) -> 4176
A28: EFFEXOR LP 37.5mg Gél. LP | B28: 1060 | C28: 960 | D28: 1290 | E28: 1681 | F28: 1565 | G28: 1470 | H28: 1640 | I28: 1696 | J28: 1872 | K28: 1760 | L28: 1270 | M28: 819 | N28: =SUM(B28:M28) -> 17083
... A39: VIAGRA 100mg Comp.Pell. | B39: 7330 | C39: 7390 | D39: 3850 | E39: 4140 | F39: 6160 | G39: 7520 | H39: 6860 | I39: 6910 | J39: 7730 | K39: 6960 | L39: 5240 | M39: 4570 | N39: =SUM(B39:M39) -> 74660
B40: =SUM(B12:B39) -> 73172 | C40: =SUM(C12:C39) -> 58184 | D40: =SUM(D12:D39) -> 55978 | E40: =SUM(E12:E39) -> 48791 | F40: =SUM(F12:F39) -> 63276 | G40: =SUM(G12:G39) -> 68212 | H40: =SUM(H12:H39) -> 57438 | I40: =SUM(I12:I39) -> 64723 | ... N40: =SUM(N12:N39) -> 750530
A43: PCT Sales Data 2026
A44: BRAND NAME | B44: 46023 | C44: 46054 | D44: 46082 | E44: 46113 | F44: 46143 | G44: 46174 | H44: 46204 | I44: 46235 | J44: 46266 | K44: 46296 | L44: 46327 | M44: 46357 | N44: Total 2026 | O44: 2025 Comparsion as on March
A45: VALPROATE Officine | B45: 4372 | C45: 5192 | D45: 1721 | E45: 2650 | N45: =SUM(B45:M45) -> 13935 | O45: =N45/N3 -> 0.18325158
A46: ZOLPIDEM | B46: 1900 | C46: 1740 | D46: 1580 | E46: 1280 | N46: =SUM(B46:M46) -> 6500 | O46: =N46/N4 -> 0.29707495
A47: METHYLPREDNISOLONE | C47: 0 | D47: 0 | N47: =SUM(B47:M47) -> 0
A48: METHOTREXATE 5mg/2ml | C48: 0 | D48: 0 | N48: =SUM(B48:M48) -> 0
A49: DOBUTAMINE | B49: 13 | C49: 1528 | D49: 527 | E49: 317 | N49: =SUM(B49:M49) -> 2385 | O49: =N49/N7 -> 0.64669197
A50: METHOTREXATE 25mg/20ml | N50: =SUM(B50:M50) -> 0
A51: METHOTREXATE 50mg/2ml | B51: 208 | C51: 51 | D51: 124 | E51: 112 | N51: =SUM(B51:M51) -> 495 | O51: =N51/N9 -> 0.72262774
A52: AZATHIOPRINE | B52: 4246 | C52: 7769 | D52: 5560 | E52: 6153 | N52: =SUM(B52:M52) -> 23728 | O52: =N52/N10 -> 0.32447216
...

Sheet Monthwise Inventory Tracker  
A2: BRAND NAME | B2: PCT Codes | C2: Annual offtake | D2: AMC | E2: Stock as on 01/05/2026 | F2: MOH
A3: VALPROATE Officine | B3: 104607 | C3: =D3*12 -> 69408 | D3: ='[1]2026-2027'!$F$2 -> 5784 | E3: ='[2]2026-2027'!$S$2 -> 25500 | F3: =E3/D3 -> 4.4087137
A4: ZOLPIDEM | B4: 104691 | C4: =D4*12 -> 21744 | D4: ='[1]2026-2027'!$F$5 -> 1812 | E4: ='[2]2026-2027'!$S$5 -> 5061 | F4: =E4/D4 -> 2.7930464
A5: METHYLPREDNISOLONE | B5: 502156
A6: METHOTREXATE 5mg/2ml | B6: 502497
A7: DOBUTAMINE | B7: 502651 | D7: ='[1]2026-2027'!$F$14 -> 406 | E7: ='[2]2026-2027'!$S$14 -> 1852 | F7: =E7/D7 -> 4.5615764
A8: METHOTREXATE 25mg/20ml | B8: 503089
A9: METHOTREXATE 50mg/2ml | B9: 503456 | D9: ='[1]2026-2027'!$F$20 -> 89 | E9: ='[2]2026-2027'!$S$20 -> 20 | F9: =E9/D9 -> 0.2247191
A10: AZATHIOPRINE | B10: 504664 | D10: ='[1]2026-2027'!$F$23 -> 6053 | E10: ='[2]2026-2027'!$S$23 -> 24107
A11: METHOTREXATE 100mg/ml (5G) | B11: 502652 | D11: ='[1]2026-2027'!$F$26 -> 5
A12: SUFENTANIL 10µg/2ml | B12: 505180 | D12: ='[1]2026-2027'!$F$29 -> 709
A13: CAPECITABINE | B13: 505500 | D13: ='[1]2026-2027'!$F$32 -> 281 | E13: ='[2]2026-2027'!$S$32 -> 5509 | F13: =E13/D13 -> 19.604982
A14: SUFENTANIL 50µg/10ml | B14: 505678 | D14: ='[1]2026-2027'!$F$35 -> 537 | E14: ='[2]2026-2027'!$S$35 -> 219 | F14: =E14/D14 -> 0.40782123
A15: PIPER/TAZO 2g/250mg | B15: 505923 | C15: =D15*12 -> 3240 | D15: ='[1]2026-2027'!$F$38 -> 270
A16: PIPER/TAZO 4g/500mg | B16: 505924
A17: LEPONEX 25mg | B17: 505441 | C17: =D17*12 -> 2928 | D17: ='[1]2026-2027'!$F$44 -> 244
A18: LEPONEX 100mg | B18: 505452 | C18: =D18*12 -> 20028 | D18: ='[1]2026-2027'!$F$47 -> 1669
A19: FLECAINE 100mg | B19: 103320 | C19: =D19*12 -> 34644 | D19: ='[1]2026-2027'!$F$50 -> 2887 | E19: ='[2]2026-2027'!$S$50 -> 22061 | F19: =E19/D19 -> 7.6414964
A20: FLECAINE LP 200mg | B20: 104408 | C20: =D20*12 -> 21096 | D20: ='[1]2026-2027'!$F$53 -> 1758 | E20: ='[2]2026-2027'!$S$53 -> 4141 | F20: =E20/D20 -> 2.3555176
A21: FLECAINE LP 50mg | B21: 104474 | C21: =D21*12 -> 18000 | D21: ='[1]2026-2027'!$F$56 -> 1500 | E21: ='[2]2026-2027'!$S$56 -> 611 | F21: =E21/D21 -> 0.40733333
A22: FLECAINE LP 100mg | B22: 104475 | C22: =D22*12 -> 55008 | D22: ='[1]2026-2027'!$F$59 -> 4584 | E22: ='[2]2026-2027'!$S$59 -> 18271 | F22: =E22/D22 -> 3.9858202
A23: XANAX RETARD 0.5mg | B23: 106742 | C23: =D23*12 -> 46368 | D23: ='[1]2026-2027'!$F$62 -> 3864 | E23: ='[2]2026-2027'!$S$62 -> 5434 | F23: =E23/D23 -> 1.4063147
A24: XANAX RETARD 1mg | B24: 106743 | C24: =D24*12 -> 56832 | D24: ='[1]2026-2027'!$F$65 -> 4736 | E24: ='[2]2026-2027'!$S$65 -> 27117 | F24: =E24/D24 -> 5.7257179
A25: XANAX 0.75mg/ml Gttes.Buv. | B25: 106744 | C25: =D25*12 -> 49332 | D25: ='[1]2026-2027'!$F$68 -> 4111 | E25: ='[2]2026-2027'!$S$68 -> 6246 | F25: =E25/D25 -> 1.5193384
A26: EFEXOR. XL 150mg Gél. LP | B26: 105522 | C26: =D26*12 -> 900 | D26: ='[1]2026-2027'!$F$71 -> 75 | E26: ='[2]2026-2027'!$S$71 -> 330 | F26: =E26/D26 -> 4.4
A27: LYRICA 75mg Gél. Bt56 | B27: 105523 | C27: =D27*12 -> 4296 | D27: ='[1]2026-2027'!$F$74 -> 358 | E27: ='[2]2026-2027'!$S$74 -> 321 | F27: =E27/D27 -> 0.89664804
A28: EFFEXOR LP 37.5mg Gél. LP | B28: 105525 | C28: =D28*12 -> 18132 | D28: ='[1]2026-2027'!$F$77 -> 1511 | E28: ='[2]2026-2027'!$S$77 -> 5350 | F28: =E28/D28 -> 3.5407015
A29: EFFEXOR LP 75mg Gél. LP | B29: 105526 | C29: =D29*12 -> 64368 | D29: ='[1]2026-2027'!$F$80 -> 5364 | E29: ='[2]2026-2027'!$S$80 -> 11064 | F29: =E29/D29 -> 2.0626398
A30: XALATAN 50mcg/ml Collyre | B30: 105527 | C30: =D30*12 -> 79728 | D30: ='[1]2026-2027'!$F$83 -> 6644 | E30: ='[2]2026-2027'!$S$83 -> 23525 | F30: =E30/D30 -> 3.5407887
A31: CADUET 10mg/10mg Comp.Pell. | B31: 105528 | C31: =D31*12 -> 3912 | D31: ='[1]2026-2027'!$F$86 -> 326 | E31: ='[2]2026-2027'!$S$86 -> 1013 | F31: =E31/D31 -> 3.107362
A32: CADUET 5mg/10mg Comp.Pell. | B32: 105529 | C32: =D32*12 -> 8796 | D32: ='[1]2026-2027'!$F$89 -> 733 | E32: ='[2]2026-2027'!$S$89 -> 2270 | F32: =E32/D32 -> 3.0968622
A33: LYRICA 150mg Gél. | B33: 105531 | C33: =D33*12 -> 6492 | D33: ='[1]2026-2027'!$F$92 -> 541 | E33: ='[2]2026-2027'!$S$92 -> 1364 | F33: =E33/D33 -> 2.5212569
A34: LYRICA 75mg Gél. Bt14 | B34: 105532 | C34: =D34*12 -> 7800 | D34: ='[1]2026-2027'!$F$95 -> 650 | E34: ='[2]2026-2027'!$S$95 -> 2912 | F34: =E34/D34 -> 4.48
A35: XALACOM 50mcg + 5mg/ml Collyre | B35: 105533 | C35: =D35*12 -> 83148 | D35: ='[1]2026-2027'!$F$98 -> 6929 | E35: ='[2]2026-2027'!$S$98 -> 29222 | F35: =E35/D35 -> 4.2173474
A36: TAHOR 80mg Comp.Pell. | B36: 105535 | C36: =D36*12 -> 2472 | D36: ='[1]2026-2027'!$F$101 -> 206 | E36: ='[2]2026-2027'!$S$101 -> 280 | F36: =E36/D36 -> 1.3592233
A37: VIAGRA 25mg Comp.Pell. | B37: 105538 | C37: =D37*12 -> 9180 | D37: ='[1]2026-2027'!$F$104 -> 765 | E37: ='[2]2026-2027'!$S$104 -> 913 | F37: =E37/D37 -> 1.1934641
A38: VIAGRA 50mg Comp.Pell. | B38: 105539 | C38: =D38*12 -> 44952 | D38: ='[1]2026-2027'!$F$107 -> 3746 | E38: ='[2]2026-2027'!$S$107 -> 12034 | F38: =E38/D38 -> 3.2124933
A39: VIAGRA 100mg Comp.Pell. | B39: 105540 | C39: =D39*12 -> 70800 | D39: ='[1]2026-2027'!$F$110 -> 5900 | E39: ='[2]2026-2027'!$S$110 -> 21397 | F39: =E39/D39 -> 3.6266102

Sheet PCT order to Viatris 
A1: Viatris product code | B1: PCT Code | C1: PRODUCT DESCRIPTION | D1: Total Ordered Qty | E1: Ordered Qty | F1: PO Number | G1: Ordered Qty | H1: PO Number | I1: Ordered Qty | J1: PO Number | K1: Ordered Qty | L1: PO Number
B2: 105528 | C2: CADUET 10mg/10mg Comp.Pell. Bt 30 | D2: =E2+G2+I2+K2 -> 6850 | E2: =E3+E4 -> 1250 | F2: 24GG10I0147 | G2: =G3+G4+G5+G6+G7+G8+G9 -> 4900 | H2: 25GG10I0087 | I2: =I3 -> 700 | J2: 25GG10I0126
E3: 500 | F3: may-26 | G3: 750 | H3: july-26 | I3: 700 | J3: august-27
E4: 750 | F4: may-26 | G4: 750 | H4: 46266
G5: 750 | H5: 46327
G6: 750 | H6: 46388
G7: 704 | H7: march-27
G8: 948 | H8: may-27
G9: 248 | H9: august-27
B10: 105529 | C10: CADUET 5mg/10mg Comp.Pell. Bt 30 | D10: =E10+G10+I10+K10 -> 3200 | E10: =E11 -> 1600 | F10: 25GG10I0087 | G10: =G11 -> 1600 | H10: 25GG10I0126
E11: 1600 | F11: june-26 | G11: 1600 | H11: august-26
B12: 105522 | C12: EFEXOR. XL 150mg Gél. LP Bt 28 | D12: =E12+G12+I12+K12 -> 600 | E12: =E13 -> 600 | F12: 26MP10I0002
E13: 600 | F13: july-26
B14: 105525 | C14: EFFEXOR 37,5 LP BT 30 | D14: =E14+G14+I14+K14 -> 8000 | E14: =E15 -> 2000 | F14: 25GG10I0087 | G14: =G15+G16 -> 6000 | H14: 25GG10I0126
E15: 2000 | F15: may-26 | G15: 4000 | H15: june-26
G16: 2000 | H16: august-26
B17: 105526 | C17: EFFEXOR 75 LP BT 30 | D17: =E17+G17+I17+K17 -> 34748 | E17: =E18 -> 1748 | F17: 25GG10I0087 | G17: =G18+G19 -> 33000 | H17: 25GG10I0126
E18: 1748 | F18: may-26 | G18: 16252 | H18: may-26
G19: 16748 | H19: july-26
B20: 105531 | C20: LYRICA 150mg Gél. Bt 56 | D20: =E20+G20+I20+K20 -> 3000 | E20: =E21 -> 1350 | F20: 25GG10I0087 | G20: =G21 -> 1650 | H20: 25GG10I0126
E21: 1350 | F21: may-26 | G21: 1650 | H21: may-26
B22: 105532 | C22: LYRICA 75mg Gél. Bt 14 | D22: =E22+G22+I22+K22 -> 2400 | E22: =E23+E24 -> 2400 | F22: 25GG10I0087
E23: 844 | F23: may-26
E24: 1556 | F24: june-26
B25: 105523 | C25: LYRICA 75mg Gél. Bt 56 | D25: =E25+G25+I25+K25 -> 2500 | E25: =E26 -> 2500 | F25: 26MP10I0002
E26: 2500 | F26: may-26
B27: 105535 | C27: TAHOR 80mg Comp pell. Bt 28 | D27: =E27+G27+I27+K27 -> 1000 | E27: =E28 -> 1000 | F27: 25GP10I0160
E28: 1000 | F28: may-26
B29: 105540 | C29: VIAGRA 100mg Comp.Pell. Bt 4 | D29: =E29+G29+I29+K29 -> 40925 | E29: =E31+E30 -> 9410 | F29: 25GP10I0102 | G29: =G31+G30 -> 5515 | H29: UG25GP10I0102 | I29: =I30 -> 16900 | J29: 25GP10I0160 | K29: =K30 -> 9100 | L29: UG25GP10I0160
E30: 6200 | F30: may-26 | G30: 3800 | H30: may-26 | I30: 16900 | J30: july-26 | K30: 9100 | L30: july-26
E31: 3210 | F31: june-26 | G31: 1715 | H31: june-26
B32: 105538 | C32: VIAGRA 25mg Comp. Pell. Bt 4 | D32: =E32+G32+I32+K32 -> 3200 | E32: =E33 -> 1920 | F32: 25GP10I0160 | G32: =G33 -> 1280 | H32: UG25GP10I0160
E33: 1920 | F33: may-26 | G33: 1280 | H33: may-26
B34: 105539 | C34: VIAGRA 50mg Comp.Pell. Bt 4 | D34: =E34+G34+I34+K34 -> 24000 | E34: =E35 -> 4875 | F34: 25GP10I0102 | G34: =G35 -> 3125 | H34: UG25GP10I0102 | I34: =I35+I36 -> 10400 | J34: 25GP10I0160 | K34: =K35+K36 -> 5600 | L34: UG25GP10I0160
E35: 4875 | F35: may-26 | G35: 3125 | H35: may-26 | I35: 5200 | J35: may-26 | K35: 2800 | L35: may-26
I36: 5200 | J36: july-26 | K36: 2800 | L36: july-26
B37: 105533 | C37: XALACOM | D37: =E37+G37+I37+K37 -> 12000 | E37: =E38 -> 12000 | F37: 25GG10I0126
E38: 12000 | F38: 46266
B39: 105527 | C39: XALATAN 50mcg/ml Collyre Fl 2.5ml (F) | D39: =E39+G39+I39+K39 -> 12000 | E39: =E40 -> 12000 | F39: 25GG10I0126
E40: 12000 | F40: july-26
...
