Workbook

Sheet Sheet1
B3: Année | C3: Mois | D3: Ventes/stock | E3: Abevmy 100 | F3: Abevmy 400 | G3: Hertraz 150 | H3: Hertraz 440 | I3: Hulio | J3: Semglee | K3: Fulphila | L3: Ogivri 150 | M3: Ogivri 420 | N3: Nepexto 25 | O3: Nepexto 50
B4: 2024 | C4: Janvier | D4: Ventes | E4: =Ventes!D4 -> 0 | F4: =Ventes!E4 -> 712 | G4: =Ventes!F4 -> 4794 | H4: =Ventes!G4 -> 0 | I4: =Ventes!H4 -> 0 | J4: =Ventes!I4 -> 899 | K4: =Ventes!J4 -> 0 | L4: 0 | M4: 0 | N4: 0 | O4: 0
B5: 2024 | C5: Janvier | D5: Stock | E5: =Stock!D4 -> 1 | F5: =Stock!E4 -> 1265 | G5: =Stock!F4 -> 11805 | H5: =Stock!G4 -> 0 | I5: =Stock!H4 -> 0 | J5: =Stock!I4 -> 42750 | K5: =Stock!J4 -> 0 | L5: 0 | M5: 0 | N5: 0 | O5: 0
B6: 2024 | C6: Fevrier | D6: Ventes | E6: =Ventes!D5 -> 1235 | F6: =Ventes!E5 -> 622 | G6: =Ventes!F5 -> 2594 | H6: =Ventes!G5 -> 0 | I6: =Ventes!H5 -> 0 | J6: =Ventes!I5 -> 1008 | K6: =Ventes!J5 -> 0 | L6: 0 | M6: 0 | N6: 0 | O6: 0
B7: 2024 | C7: Fevrier | D7: Stock | E7: =Stock!D5 -> 386 | F7: =Stock!E5 -> 633 | G7: =Stock!F5 -> 9211 | H7: =Stock!G5 -> 0 | I7: =Stock!H5 -> 0 | J7: =Stock!I5 -> 41742 | K7: =Stock!J5 -> 0 | L7: 0 | M7: 0 | N7: 0 | O7: 0
B8: 2024 | C8: Mars | D8: Ventes | E8: =Ventes!D6 -> 1051 | F8: =Ventes!E6 -> 572 | G8: =Ventes!F6 -> 3829 | H8: =Ventes!G6 -> 0 | I8: =Ventes!H6 -> 0 | J8: =Ventes!I6 -> 820 | K8: =Ventes!J6 -> 0 | L8: 0 | M8: 0 | N8: 0 | O8: 0
B9: 2024 | C9: Mars | D9: Stock | E9: =Stock!D6 -> 2715 | F9: =Stock!E6 -> 61 | G9: =Stock!F6 -> 5382 | H9: =Stock!G6 -> 0 | I9: =Stock!H6 -> 0 | J9: =Stock!I6 -> 40922 | K9: =Stock!J6 -> 0 | L9: 0 | M9: 0 | N9: 0 | O9: 0
B10: 2024 | C10: Avril | D10: Ventes | E10: =Ventes!D7 -> 418 | F10: =Ventes!E7 -> 60 | G10: =Ventes!F7 -> 4539 | H10: =Ventes!G7 -> 0 | I10: =Ventes!H7 -> 0 | J10: =Ventes!I7 -> 853 | K10: =Ventes!J7 -> 0 | L10: 0 | M10: 0 | N10: 0 | O10: 0
B11: 2024 | C11: Avril | D11: Stock | E11: =Stock!D7 -> 7497 | F11: =Stock!E7 -> 3455 | G11: =Stock!F7 -> 7444 | H11: =Stock!G7 -> 6189 | I11: =Stock!H7 -> 0 | J11: =Stock!I7 -> 40069 | K11: =Stock!J7 -> 0 | L11: 0 | M11: 0 | N11: 0 | O11: 0
B12: 2024 | C12: Mai | D12: Ventes | E12: =Ventes!D8 -> 1011 | F12: =Ventes!E8 -> 1445 | G12: =Ventes!F8 -> 2958 | H12: =Ventes!G8 -> 0 | I12: =Ventes!H8 -> 0 | J12: =Ventes!I8 -> 1154 | K12: =Ventes!J8 -> 0 | L12: 0 | M12: 0 | N12: 0 | O12: 0
B13: 2024 | C13: Mai | D13: Stock | E13: =Stock!D8 -> 6486 | F13: =Stock!E8 -> 2010 | G13: =Stock!F8 -> 4486 | H13: =Stock!G8 -> 6189 | I13: =Stock!H8 -> 0 | J13: =Stock!I8 -> 38915 | K13: =Stock!J8 -> 0 | L13: 0 | M13: 0 | N13: 0 | O13: 0
B14: 2024 | C14: Juin | D14: Ventes | E14: =Ventes!D9 -> 579 | F14: =Ventes!E9 -> 529 | G14: =Ventes!F9 -> 3027 | H14: =Ventes!G9 -> 0 | I14: =Ventes!H9 -> 0 | J14: =Ventes!I9 -> 1006 | K14: =Ventes!J9 -> 0 | L14: 0 | M14: 0 | N14: 0 | O14: 0
B15: 2024 | C15: Juin | D15: Stock | E15: =Stock!D9 -> 5907 | F15: =Stock!E9 -> 1481 | G15: =Stock!F9 -> 1459 | H15: =Stock!G9 -> 6189 | I15: =Stock!H9 -> 0 | J15: =Stock!I9 -> 37909 | K15: =Stock!J9 -> 0 | L15: 0 | M15: 0 | N15: 0 | O15: 0
B16: 2024 | C16: Juillet | D16: Ventes | E16: =Ventes!D10 -> 829 | F16: =Ventes!E10 -> 794 | G16: =Ventes!F10 -> 2661 | H16: =Ventes!G10 -> 1 | I16: =Ventes!H10 -> 0 | J16: =Ventes!I10 -> 913 | K16: =Ventes!J10 -> 0 | L16: 0 | M16: 0 | N16: 0 | O16: 0
B17: 2024 | C17: Juillet | D17: Stock | E17: =Stock!D10 -> 7328 | F17: =Stock!E10 -> 2172 | G17: =Stock!F10 -> 10298 | H17: =Stock!G10 -> 9339 | I17: =Stock!H10 -> 0 | J17: =Stock!I10 -> 36996 | K17: =Stock!J10 -> 0 | L17: 0 | M17: 0 | N17: 0 | O17: 0
B18: 2024 | C18: Aout | D18: Ventes | E18: =Ventes!D11 -> 738 | F18: =Ventes!E11 -> 652 | G18: =Ventes!F11 -> 1554 | H18: =Ventes!G11 -> 1379 | I18: =Ventes!H11 -> 0 | J18: =Ventes!I11 -> 798 | K18: =Ventes!J11 -> 0 | L18: 0 | M18: 0 | N18: 0 | O18: 0
B19: 2024 | C19: Aout | D19: Stock | E19: =Stock!D11 -> 6590 | F19: =Stock!E11 -> 1520 | G19: =Stock!F11 -> 8744 | H19: =Stock!G11 -> 7960 | I19: =Stock!H11 -> 0 | J19: =Stock!I11 -> 36198 | K19: =Stock!J11 -> 0 | L19: 0 | M19: 0 | N19: 0 | O19: 0
B20: 2024 | C20: Sept | D20: Ventes | E20: =Ventes!D12 -> 1224 | F20: =Ventes!E12 -> 979 | G20: =Ventes!F12 -> 466 | H20: =Ventes!G12 -> 1311 | I20: =Ventes!H12 -> 0 | J20: =Ventes!I12 -> 1020 | K20: =Ventes!J12 -> 0 | L20: 0 | M20: 0 | N20: 0 | O20: 0
B21: 2024 | C21: Sept | D21: Stock | E21: =Stock!D12 -> 5366 | F21: =Stock!E12 -> 4041 | G21: =Stock!F12 -> 8278 | H21: =Stock!G12 -> 6649 | I21: =Stock!H12 -> 0 | J21: =Stock!I12 -> 35178 | K21: =Stock!J12 -> 0 | L21: 0 | M21: 0 | N21: 0 | O21: 0
B22: 2024 | C22: Oct | D22: Ventes | E22: =Ventes!D13 -> 636 | F22: =Ventes!E13 -> 1048 | G22: =Ventes!F13 -> 420 | H22: =Ventes!G13 -> 1433 | I22: =Ventes!H13 -> 0 | J22: =Ventes!I13 -> 949 | K22: =Ventes!J13 -> 0 | L22: 0 | M22: 0 | N22: 0 | O22: 0
B23: 2024 | C23: Oct | D23: Stock | E23: =Stock!D13 -> 7230 | F23: =Stock!E13 -> 2993 | G23: =Stock!F13 -> 14757 | H23: =Stock!G13 -> 7966 | I23: =Stock!H13 -> 0 | J23: =Stock!I13 -> 34107 | K23: =Stock!J13 -> 0 | L23: 0 | M23: 0 | N23: 0 | O23: 0
B24: 2024 | C24: Nov | D24: Ventes | E24: =Ventes!D14 -> 1094 | F24: =Ventes!E14 -> 686 | G24: =Ventes!F14 -> 398 | H24: =Ventes!G14 -> 925 | I24: =Ventes!H14 -> 0 | J24: =Ventes!I14 -> 880 | K24: =Ventes!J14 -> 0 | L24: 0 | M24: 0 | N24: 0 | O24: 0
B25: 2024 | C25: Nov | D25: Stock | E25: =Stock!D14 -> 6136 | F25: =Stock!E14 -> 2307 | G25: =Stock!F14 -> 14359 | H25: =Stock!G14 -> 7041 | I25: =Stock!H14 -> 0 | J25: =Stock!I14 -> 33227 | K25: =Stock!J14 -> 0 | L25: 0 | M25: 0 | N25: 0 | O25: 0
B26: 2024 | C26: Dec | D26: Ventes | E26: =Ventes!D15 -> 1114 | F26: =Ventes!E15 -> 943 | G26: =Ventes!F15 -> 670 | H26: =Ventes!G15 -> 1512 | I26: =Ventes!H15 -> 0 | J26: =Ventes!I15 -> 930 | K26: =Ventes!J15 -> 0 | L26: 0 | M26: 0 | N26: 0 | O26: 0
B27: 2024 | C27: Dec | D27: Stock | E27: =Stock!D15 -> 9022 | F27: =Stock!E15 -> 6864 | G27: =Stock!F15 -> 13689 | H27: =Stock!G15 -> 7949 | I27: =Stock!H15 -> 0 | J27: =Stock!I15 -> 32297 | K27: =Stock!J15 -> 0 | L27: 0 | M27: 0 | N27: 0 | O27: 0
B28: 2025 | C28: Janvier | D28: Ventes | E28: =Ventes!D16 -> 1063 | F28: =Ventes!E16 -> 976 | G28: =Ventes!F16 -> 205 | H28: =Ventes!G16 -> 1624 | I28: =Ventes!H16 -> 0 | J28: =Ventes!I16 -> 963 | K28: =Ventes!J16 -> 0 | L28: 0 | M28: 0 | N28: 0 | O28: 0
B29: 2025 | C29: Janvier | D29: Stock | E29: =Stock!D16 -> 7959 | F29: =Stock!E16 -> 9017 | G29: =Stock!F16 -> 18478 | H29: =Stock!G16 -> 7954 | I29: =Stock!H16 -> 0 | J29: =Stock!I16 -> 31334 | K29: =Stock!J16 -> 0 | L29: 0 | M29: 0 | N29: 0 | O29: 0
B30: 2025 | C30: Fevrier | D30: Ventes | E30: =Ventes!D17 -> 315 | F30: =Ventes!E17 -> 337 | G30: =Ventes!F17 -> 168 | H30: =Ventes!G17 -> 619 | I30: =Ventes!H17 -> 0 | J30: =Ventes!I17 -> 905 | K30: =Ventes!J17 -> 0 | L30: 0 | M30: 0 | N30: 0 | O30: 0
B31: 2025 | C31: Fevrier | D31: Stock | E31: =Stock!D17 -> 10144 | F31: =Stock!E17 -> 9680 | G31: =Stock!F17 -> 18310 | H31: =Stock!G17 -> 7335 | I31: =Stock!H17 -> 0 | J31: =Stock!I17 -> 30429 | K31: =Stock!J17 -> 0 | L31: 0 | M31: 0 | N31: 0 | O31: 0
B32: 2025 | C32: Mars | D32: Ventes | E32: =Ventes!D18 -> 1138 | F32: =Ventes!E18 -> 959 | G32: =Ventes!F18 -> 179 | H32: =Ventes!G18 -> 1493 | I32: =Ventes!H18 -> 0 | J32: =Ventes!I18 -> 1109 | K32: =Ventes!J18 -> 0 | L32: 0 | M32: 0 | N32: 0 | O32: 0
B33: 2025 | C33: Mars | D33: Stock | E33: =Stock!D18 -> 9006 | F33: =Stock!E18 -> 13088 | G33: =Stock!F18 -> 18131 | H33: =Stock!G18 -> 5842 | I33: =Stock!H18 -> 0 | J33: =Stock!I18 -> 29310 | K33: =Stock!J18 -> 0 | L33: 0 | M33: 0 | N33: 0 | O33: 0
B34: 2025 | C34: Avril | D34: Ventes | E34: =Ventes!D19 -> 898 | F34: =Ventes!E19 -> 717 | G34: =Ventes!F19 -> 336 | H34: =Ventes!G19 -> 1286 | I34: =Ventes!H19 -> 0 | J34: =Ventes!I19 -> 1049 | K34: =Ventes!J19 -> 0 | L34: 0 | M34: 0 | N34: 0 | O34: 0
B35: 2025 | C35: Avril | D35: Stock | E35: =Stock!D19 -> 8108 | F35: =Stock!E19 -> 12371 | G35: =Stock!F19 -> 17795 | H35: =Stock!G19 -> 7306 | I35: =Stock!H19 -> 0 | J35: =Stock!I19 -> 28271 | K35: =Stock!J19 -> 0 | L35: 0 | M35: 0 | N35: 0 | O35: 0
B36: 2025 | C36: Mai | D36: Ventes | E36: =Ventes!D20 -> 740 | F36: =Ventes!E20 -> 1067 | G36: =Ventes!F20 -> 519 | H36: =Ventes!G20 -> 943 | I36: =Ventes!H20 -> 0 | J36: =Ventes!I20 -> 1145 | K36: =Ventes!J20 -> 0 | L36: 0 | M36: 0 | N36: 0 | O36: 0
B37: 2025 | C37: Mai | D37: Stock | E37: =Stock!D20 -> 7368 | F37: =Stock!E20 -> 11304 | G37: =Stock!F20 -> 17276 | H37: =Stock!G20 -> 6363 | I37: =Stock!H20 -> 0 | J37: =Stock!I20 -> 27126 | K37: =Stock!J20 -> 0 | L37: 0 | M37: 0 | N37: 0 | O37: 0
B38: 2025 | C38: Juin | D38: Ventes | E38: =Ventes!D21 -> 768 | F38: =Ventes!E21 -> 826 | G38: =Ventes!F21 -> 265 | H38: =Ventes!G21 -> 1246 | I38: =Ventes!H21 -> 0 | J38: =Ventes!I21 -> 839 | K38: =Ventes!J21 -> 0 | L38: 0 | M38: 0 | N38: 0 | O38: 0
B39: 2025 | C39: Juin | D39: Stock | E39: =Stock!D21 -> 9350 | F39: =Stock!E21 -> 12248 | G39: =Stock!F21 -> 17011 | H39: =Stock!G21 -> 11228 | I39: =Stock!H21 -> 0 | J39: =Stock!I21 -> 26287 | K39: =Stock!J21 -> 0 | L39: 0 | M39: 0 | N39: 0 | O39: 0
B40: 2025 | C40: Juillet | D40: Ventes | E40: =Ventes!D22 -> 975 | F40: =Ventes!E22 -> 658 | G40: =Ventes!F22 -> 433 | H40: =Ventes!G22 -> 1024 | I40: =Ventes!H22 -> 0 | J40: =Ventes!I22 -> 1210 | K40: =Ventes!J22 -> 0 | L40: 0 | M40: 0 | N40: 0 | O40: 0
B41: 2025 | C41: Juillet | D41: Stock | E41: =Stock!D22 -> 8375 | F41: =Stock!E22 -> 11590 | G41: =Stock!F22 -> 16578 | H41: =Stock!G22 -> 10204 | I41: =Stock!H22 -> 2000 | J41: =Stock!I22 -> 25077 | K41: =Stock!J22 -> 0 | L41: 0 | M41: 0 | N41: 0 | O41: 0
B42: 2025 | C42: Aout | D42: Ventes | E42: =Ventes!D23 -> 1322 | F42: =Ventes!E23 -> 1057 | G42: =Ventes!F23 -> 340 | H42: =Ventes!G23 -> 1332 | I42: =Ventes!H23 -> 622 | J42: =Ventes!I23 -> 730 | K42: =Ventes!J23 -> 0 | L42: 0 | M42: 0 | N42: 0 | O42: 0
...

Sheet Ventes
B2: Ventes
B3: Année | C3: Mois | D3: Abevmy 100 | E3: Abevmy 400 | F3: Hertraz 150 | G3: Hertraz 440 | H3: Hulio | I3: Semglee | J3: Fulphila | K3: Ogivri 150 | L3: Ogivri 420 | M3: Nepexto 25 | N3: Nepexto 50
B4: 2024 | C4: Janvier | D4: 0 | E4: 712 | F4: 4794 | G4: 0 | H4: 0 | I4: 899 | J4: 0 | K4: 0 | L4: 0 | M4: 0 | N4: 0
B5: 2024 | C5: Fevrier | D5: 1235 | E5: 622 | F5: 2594 | G5: 0 | H5: 0 | I5: 1008 | J5: 0 | K5: 0 | L5: 0 | M5: 0 | N5: 0
B6: 2024 | C6: Mars | D6: 1051 | E6: 572 | F6: 3829 | G6: 0 | H6: 0 | I6: 820 | J6: 0 | K6: 0 | L6: 0 | M6: 0 | N6: 0
B7: 2024 | C7: Avril | D7: 418 | E7: 60 | F7: 4539 | G7: 0 | H7: 0 | I7: 853 | J7: 0 | K7: 0 | L7: 0 | M7: 0 | N7: 0
B8: 2024 | C8: Mai | D8: 1011 | E8: 1445 | F8: 2958 | G8: 0 | H8: 0 | I8: 1154 | J8: 0 | K8: 0 | L8: 0 | M8: 0 | N8: 0
B9: 2024 | C9: Juin | D9: 579 | E9: 529 | F9: 3027 | G9: 0 | H9: 0 | I9: 1006 | J9: 0 | K9: 0 | L9: 0 | M9: 0 | N9: 0
B10: 2024 | C10: Juillet | D10: 829 | E10: 794 | F10: 2661 | G10: 1 | H10: 0 | I10: 913 | J10: 0 | K10: 0 | L10: 0 | M10: 0 | N10: 0
B11: 2024 | C11: Aout | D11: 738 | E11: 652 | F11: 1554 | G11: 1379 | H11: 0 | I11: 798 | J11: 0 | K11: 0 | L11: 0 | M11: 0 | N11: 0
B12: 2024 | C12: Sept | D12: 1224 | E12: 979 | F12: 466 | G12: 1311 | H12: 0 | I12: 1020 | J12: 0 | K12: 0 | L12: 0 | M12: 0 | N12: 0
B13: 2024 | C13: Oct | D13: 636 | E13: 1048 | F13: 420 | G13: 1433 | H13: 0 | I13: 949 | J13: 0 | K13: 0 | L13: 0 | M13: 0 | N13: 0
B14: 2024 | C14: Nov | D14: 1094 | E14: 686 | F14: 398 | G14: 925 | H14: 0 | I14: 880 | J14: 0 | K14: 0 | L14: 0 | M14: 0 | N14: 0
B15: 2024 | C15: Dec | D15: 1114 | E15: 943 | F15: 670 | G15: 1512 | H15: 0 | I15: 930 | J15: 0 | K15: 0 | L15: 0 | M15: 0 | N15: 0
... B36: 2026 | C36: Sept | D36: 942 | E36: 10 | F36: 4466 | G36: 0 | H36: 587 | I36: 0 | J36: 16 | K36: 0 | L36: 0 | M36: 0 | N36: 303
B37: 2026 | C37: Oct
B38: 2026 | C38: Nov
B39: 2026 | C39: Déc

Sheet Stock
B2: Stock
B3: Année | C3: Mois | D3: Abevmy 100 | E3: Abevmy 400 | F3: Hertraz 150 | G3: Hertraz 440 | H3: Hulio | I3: Semglee | J3: Fulphila | K3: Ogivri 150 | L3: Ogivri 420 | M3: Nepexto 25 | N3: Nepexto 50
B4: 2024 | C4: Janvier | D4: 1 | E4: 1265 | F4: 11805 | G4: 0 | H4: 0 | I4: 42750 | J4: 0 | K4: 0 | L4: 0 | M4: 0 | N4: 0
B5: 2024 | C5: Fevrier | D5: 386 | E5: 633 | F5: 9211 | G5: 0 | H5: 0 | I5: 41742 | J5: 0 | K5: 0 | L5: 0 | M5: 0 | N5: 0
B6: 2024 | C6: Mars | D6: 2715 | E6: 61 | F6: 5382 | G6: 0 | H6: 0 | I6: 40922 | J6: 0 | K6: 0 | L6: 0 | M6: 0 | N6: 0
B7: 2024 | C7: Avril | D7: 7497 | E7: 3455 | F7: 7444 | G7: 6189 | H7: 0 | I7: 40069 | J7: 0 | K7: 0 | L7: 0 | M7: 0 | N7: 0
B8: 2024 | C8: Mai | D8: 6486 | E8: 2010 | F8: 4486 | G8: 6189 | H8: 0 | I8: 38915 | J8: 0 | K8: 0 | L8: 0 | M8: 0 | N8: 0
B9: 2024 | C9: Juin | D9: 5907 | E9: 1481 | F9: 1459 | G9: 6189 | H9: 0 | I9: 37909 | J9: 0 | K9: 0 | L9: 0 | M9: 0 | N9: 0
B10: 2024 | C10: Juillet | D10: 7328 | E10: 2172 | F10: 10298 | G10: 9339 | H10: 0 | I10: 36996 | J10: 0 | K10: 0 | L10: 0 | M10: 0 | N10: 0
B11: 2024 | C11: Aout | D11: 6590 | E11: 1520 | F11: 8744 | G11: 7960 | H11: 0 | I11: 36198 | J11: 0 | K11: 0 | L11: 0 | M11: 0 | N11: 0
B12: 2024 | C12: Sept | D12: 5366 | E12: 4041 | F12: 8278 | G12: 6649 | H12: 0 | I12: 35178 | J12: 0 | K12: 0 | L12: 0 | M12: 0 | N12: 0
B13: 2024 | C13: Oct | D13: 7230 | E13: 2993 | F13: 14757 | G13: 7966 | H13: 0 | I13: 34107 | J13: 0 | K13: 0 | L13: 0 | M13: 0 | N13: 0
B14: 2024 | C14: Nov | D14: 6136 | E14: 2307 | F14: 14359 | G14: 7041 | H14: 0 | I14: 33227 | J14: 0 | K14: 0 | L14: 0 | M14: 0 | N14: 0
B15: 2024 | C15: Dec | D15: 9022 | E15: 6864 | F15: 13689 | G15: 7949 | H15: 0 | I15: 32297 | J15: 0 | K15: 0 | L15: 0 | M15: 0 | N15: 0
... B36: 2026 | C36: Sept | D36: 504 | E36: 13 | F36: 6272 | G36: 0 | H36: 4107 | I36: 0 | J36: 1887 | K36: 0 | L36: 0 | M36: 0 | N36: 5138
B37: 2026 | C37: Oct
B38: 2026 | C38: Nov
B39: 2026 | C39: Déc
